2022-03-28 16:17:07,239 - checking_the_input - 151 - произошла ошибка: 
Traceback (most recent call last):
  File "/home/dok2412/PycharmProjects/python_basic/python_basic/python_basic_diploma/main.py", line 137, in checking_the_input
    if 0 < int(message.text) < 25:
ValueError: invalid literal for int() with base 10: 'вы'
2022-03-28 16:20:09,321 - checking_the_input - 153 - произошла ошибка: 
Traceback (most recent call last):
  File "/home/dok2412/PycharmProjects/python_basic/python_basic/python_basic_diploma/main.py", line 139, in checking_the_input
    if 0 < int(message.text) < 25:
ValueError: invalid literal for int() with base 10: 'ж'
2022-03-28 16:20:20,527 - getting_photos - 251 - произошла ошибка: 
Traceback (most recent call last):
  File "/home/dok2412/PycharmProjects/python_basic/python_basic/python_basic_diploma/main.py", line 229, in getting_photos
    if int(message.text) > 0:
ValueError: invalid literal for int() with base 10: 'ж'
2022-03-28 16:27:31,149 - checking_the_input - 153 - произошла ошибка: 
Traceback (most recent call last):
  File "/home/dok2412/PycharmProjects/python_basic/python_basic/python_basic_diploma/main.py", line 139, in checking_the_input
    if 0 < int(message.text) < 25:
ValueError: invalid literal for int() with base 10: 'д'
2022-03-28 16:28:02,528 - minimum_price - 276 - произошла ошибка: 
Traceback (most recent call last):
  File "/home/dok2412/PycharmProjects/python_basic/python_basic/python_basic_diploma/main.py", line 267, in minimum_price
    if int(message.text) < 0:
ValueError: invalid literal for int() with base 10: 'ж'
2022-03-28 16:29:49,974 - max_price - 300 - произошла ошибка: 
Traceback (most recent call last):
  File "/home/dok2412/PycharmProjects/python_basic/python_basic/python_basic_diploma/main.py", line 291, in max_price
    if int(message.text) < 0 or int(message.text) < user.minimum_price:
ValueError: invalid literal for int() with base 10: 'ж'
2022-03-28 16:29:56,545 - distance_center - 342 - произошла ошибка: 
Traceback (most recent call last):
  File "/home/dok2412/PycharmProjects/python_basic/python_basic/python_basic_diploma/main.py", line 317, in distance_center
    if int(message.text) < 0:
ValueError: invalid literal for int() with base 10: 'д'
2022-03-28 16:40:54,144 - checking_the_input - 153 - произошла ошибка: 
Traceback (most recent call last):
  File "/home/dok2412/PycharmProjects/python_basic/python_basic/python_basic_diploma/main.py", line 139, in checking_the_input
    if 0 < int(message.text) < 25:
ValueError: invalid literal for int() with base 10: 'ж'
2022-03-28 16:42:16,996 - checking_the_input - 153 - произошла ошибка: 
Traceback (most recent call last):
  File "/home/dok2412/PycharmProjects/python_basic/python_basic/python_basic_diploma/main.py", line 139, in checking_the_input
    if 0 < int(message.text) < 25:
ValueError: invalid literal for int() with base 10: 'о'
2022-03-28 16:49:27,664 - distance_center - 345 - произошла ошибка: 
Traceback (most recent call last):
  File "/home/dok2412/PycharmProjects/python_basic/python_basic/python_basic_diploma/main.py", line 317, in distance_center
    if int(message.text) < 0:
ValueError: invalid literal for int() with base 10: 'ж'
2022-03-28 16:59:40,255 - max_price - 300 - произошла ошибка: 
Traceback (most recent call last):
  File "/home/dok2412/PycharmProjects/python_basic/python_basic/python_basic_diploma/main.py", line 291, in max_price
    if int(message.text) < 0 or int(message.text) < user.minimum_price:
ValueError: invalid literal for int() with base 10: 'сорок тысяч'
2022-03-28 16:59:50,199 - distance_center - 345 - произошла ошибка: 
Traceback (most recent call last):
  File "/home/dok2412/PycharmProjects/python_basic/python_basic/python_basic_diploma/main.py", line 317, in distance_center
    if int(message.text) < 0:
ValueError: invalid literal for int() with base 10: 'км'
2022-03-28 17:00:00,270 - distance_center - 345 - произошла ошибка: 
Traceback (most recent call last):
  File "/home/dok2412/PycharmProjects/python_basic/python_basic/python_basic_diploma/main.py", line 323, in distance_center
    user.hotel = bestdeal.sorting_hotels(user)
  File "/home/dok2412/PycharmProjects/python_basic/python_basic/python_basic_diploma/selection/bestdeal.py", line 46, in sorting_hotels
    if int(user.minimum_price) < int(prise_reconciliation) < int(user.max_price) and int(distance_center) < int(user.to_the_center):
ValueError: invalid literal for int() with base 10: ''
2022-03-28 17:00:38,107 - distance_center - 345 - произошла ошибка: 
Traceback (most recent call last):
  File "/home/dok2412/PycharmProjects/python_basic/python_basic/python_basic_diploma/main.py", line 323, in distance_center
    user.hotel = bestdeal.sorting_hotels(user)
  File "/home/dok2412/PycharmProjects/python_basic/python_basic/python_basic_diploma/selection/bestdeal.py", line 46, in sorting_hotels
    if int(user.minimum_price) < int(prise_reconciliation) < int(user.max_price) and int(distance_center) < int(user.to_the_center):
ValueError: invalid literal for int() with base 10: ''
2022-03-28 17:02:05,611 - distance_center - 345 - произошла ошибка: 
Traceback (most recent call last):
  File "/home/dok2412/PycharmProjects/python_basic/python_basic/python_basic_diploma/main.py", line 323, in distance_center
    user.hotel = bestdeal.sorting_hotels(user)
  File "/home/dok2412/PycharmProjects/python_basic/python_basic/python_basic_diploma/selection/bestdeal.py", line 46, in sorting_hotels
    if int(user.minimum_price) < int(prise_reconciliation) < int(user.max_price) and int(distance_center) < int(user.to_the_center):
ValueError: invalid literal for int() with base 10: ''
2022-03-28 17:04:14,170 - checking_the_input - 153 - произошла ошибка: 
Traceback (most recent call last):
  File "/home/dok2412/PycharmProjects/python_basic/python_basic/python_basic_diploma/main.py", line 139, in checking_the_input
    if 0 < int(message.text) < 25:
ValueError: invalid literal for int() with base 10: 'дл'
2022-03-28 17:06:22,896 - distance_center - 345 - произошла ошибка: 
Traceback (most recent call last):
  File "/home/dok2412/PycharmProjects/python_basic/python_basic/python_basic_diploma/main.py", line 317, in distance_center
    if int(message.text) <= 0:
ValueError: invalid literal for int() with base 10: 'па'
2022-03-28 17:06:29,804 - distance_center - 345 - произошла ошибка: 
Traceback (most recent call last):
  File "/home/dok2412/PycharmProjects/python_basic/python_basic/python_basic_diploma/main.py", line 323, in distance_center
    user.hotel = bestdeal.sorting_hotels(user)
  File "/home/dok2412/PycharmProjects/python_basic/python_basic/python_basic_diploma/selection/bestdeal.py", line 46, in sorting_hotels
    if int(user.minimum_price) < int(prise_reconciliation) < int(user.max_price) and int(distance_center) < int(user.to_the_center):
ValueError: invalid literal for int() with base 10: ''
2022-03-28 17:09:04,686 - distance_center - 345 - произошла ошибка: 
Traceback (most recent call last):
  File "/home/dok2412/PycharmProjects/python_basic/python_basic/python_basic_diploma/main.py", line 323, in distance_center
    user.hotel = bestdeal.sorting_hotels(user)
  File "/home/dok2412/PycharmProjects/python_basic/python_basic/python_basic_diploma/selection/bestdeal.py", line 46, in sorting_hotels
    if int(user.minimum_price) < int(prise_reconciliation) < int(user.max_price) and int(distance_center) < int(user.to_the_center):
ValueError: invalid literal for int() with base 10: ''
2022-03-28 17:24:11,807 - minimum_price - 276 - произошла ошибка: 
Traceback (most recent call last):
  File "/home/dok2412/PycharmProjects/python_basic/python_basic/python_basic_diploma/main.py", line 267, in minimum_price
    if int(message.text) <= 0:
ValueError: invalid literal for int() with base 10: 'ж'
2022-03-28 17:25:11,379 - minimum_price - 276 - произошла ошибка: 
Traceback (most recent call last):
  File "/home/dok2412/PycharmProjects/python_basic/python_basic/python_basic_diploma/main.py", line 267, in minimum_price
    if int(message.text) <= 0:
ValueError: invalid literal for int() with base 10: 'ж'
2022-03-28 17:33:06,757 - checking_the_input - 153 - произошла ошибка: 
Traceback (most recent call last):
  File "/home/dok2412/PycharmProjects/python_basic/python_basic/python_basic_diploma/main.py", line 139, in checking_the_input
    if 0 < int(message.text) < 25:
ValueError: invalid literal for int() with base 10: 'л'
2022-03-28 17:33:26,213 - minimum_price - 276 - произошла ошибка: 
Traceback (most recent call last):
  File "/home/dok2412/PycharmProjects/python_basic/python_basic/python_basic_diploma/main.py", line 267, in minimum_price
    if int(message.text) <= 0:
ValueError: invalid literal for int() with base 10: 'дл'
2022-03-28 17:33:32,538 - max_price - 300 - произошла ошибка: 
Traceback (most recent call last):
  File "/home/dok2412/PycharmProjects/python_basic/python_basic/python_basic_diploma/main.py", line 291, in max_price
    if int(message.text) < 0 or int(message.text) < user.minimum_price:
ValueError: invalid literal for int() with base 10: 'жд'
2022-03-28 17:33:44,626 - distance_center - 347 - произошла ошибка: 
Traceback (most recent call last):
  File "/home/dok2412/PycharmProjects/python_basic/python_basic/python_basic_diploma/main.py", line 317, in distance_center
    if int(message.text) <= 0:
ValueError: invalid literal for int() with base 10: 'дл'
2022-04-04 17:08:37,527 - getting_photos - 258 - произошла ошибка: 
Traceback (most recent call last):
  File "/home/dok2412/PycharmProjects/python_basic/python_basic/python_basic_diploma/main.py", line 241, in getting_photos
    withdrawal_of_hotels(user)
  File "/home/dok2412/PycharmProjects/python_basic/python_basic/python_basic_diploma/main.py", line 228, in withdrawal_of_hotels
    bot.send_media_group(message.chat.id, media=media)
  File "/usr/local/lib/python3.9/dist-packages/telebot/__init__.py", line 1355, in send_media_group
    result = apihelper.send_media_group(
  File "/usr/local/lib/python3.9/dist-packages/telebot/apihelper.py", line 496, in send_media_group
    return _make_request(
  File "/usr/local/lib/python3.9/dist-packages/telebot/apihelper.py", line 157, in _make_request
    json_result = _check_result(method_name, result)
  File "/usr/local/lib/python3.9/dist-packages/telebot/apihelper.py", line 184, in _check_result
    raise ApiTelegramException(method_name, result, result_json)
telebot.apihelper.ApiTelegramException: A request to the Telegram API was unsuccessful. Error code: 400. Description: Bad Request: group send failed
2022-04-04 17:10:20,283 - getting_photos - 258 - произошла ошибка: 
Traceback (most recent call last):
  File "/home/dok2412/PycharmProjects/python_basic/python_basic/python_basic_diploma/main.py", line 241, in getting_photos
    withdrawal_of_hotels(user)
  File "/home/dok2412/PycharmProjects/python_basic/python_basic/python_basic_diploma/main.py", line 230, in withdrawal_of_hotels
    sqlbase.connecting_to_database(user, 'добавление')
  File "/home/dok2412/PycharmProjects/python_basic/python_basic/python_basic_diploma/sqlbase.py", line 43, in connecting_to_database
    data_hotel = json.dumps(user.hotel)
  File "/usr/lib/python3.9/json/__init__.py", line 231, in dumps
    return _default_encoder.encode(obj)
  File "/usr/lib/python3.9/json/encoder.py", line 199, in encode
    chunks = self.iterencode(o, _one_shot=True)
  File "/usr/lib/python3.9/json/encoder.py", line 257, in iterencode
    return _iterencode(o, 0)
  File "/usr/lib/python3.9/json/encoder.py", line 179, in default
    raise TypeError(f'Object of type {o.__class__.__name__} '
TypeError: Object of type InputMediaPhoto is not JSON serializable
2022-04-04 17:12:30,487 - getting_photos - 258 - произошла ошибка: 
Traceback (most recent call last):
  File "/home/dok2412/PycharmProjects/python_basic/python_basic/python_basic_diploma/main.py", line 241, in getting_photos
    withdrawal_of_hotels(user)
  File "/home/dok2412/PycharmProjects/python_basic/python_basic/python_basic_diploma/main.py", line 230, in withdrawal_of_hotels
    sqlbase.connecting_to_database(user, 'добавление')
  File "/home/dok2412/PycharmProjects/python_basic/python_basic/python_basic_diploma/sqlbase.py", line 43, in connecting_to_database
    data_hotel = json.dumps(user.hotel)
  File "/usr/lib/python3.9/json/__init__.py", line 231, in dumps
    return _default_encoder.encode(obj)
  File "/usr/lib/python3.9/json/encoder.py", line 199, in encode
    chunks = self.iterencode(o, _one_shot=True)
  File "/usr/lib/python3.9/json/encoder.py", line 257, in iterencode
    return _iterencode(o, 0)
  File "/usr/lib/python3.9/json/encoder.py", line 179, in default
    raise TypeError(f'Object of type {o.__class__.__name__} '
TypeError: Object of type InputMediaPhoto is not JSON serializable
2022-04-04 17:15:46,178 - getting_photos - 258 - произошла ошибка: 
Traceback (most recent call last):
  File "/home/dok2412/PycharmProjects/python_basic/python_basic/python_basic_diploma/main.py", line 241, in getting_photos
    withdrawal_of_hotels(user)
  File "/home/dok2412/PycharmProjects/python_basic/python_basic/python_basic_diploma/main.py", line 230, in withdrawal_of_hotels
    sqlbase.connecting_to_database(user, 'добавление')
  File "/home/dok2412/PycharmProjects/python_basic/python_basic/python_basic_diploma/sqlbase.py", line 43, in connecting_to_database
    data_hotel = json.dumps(user.hotel)
  File "/usr/lib/python3.9/json/__init__.py", line 231, in dumps
    return _default_encoder.encode(obj)
  File "/usr/lib/python3.9/json/encoder.py", line 199, in encode
    chunks = self.iterencode(o, _one_shot=True)
  File "/usr/lib/python3.9/json/encoder.py", line 257, in iterencode
    return _iterencode(o, 0)
  File "/usr/lib/python3.9/json/encoder.py", line 179, in default
    raise TypeError(f'Object of type {o.__class__.__name__} '
TypeError: Object of type InputMediaPhoto is not JSON serializable
2022-04-04 17:16:59,913 - getting_photos - 258 - произошла ошибка: 
Traceback (most recent call last):
  File "/home/dok2412/PycharmProjects/python_basic/python_basic/python_basic_diploma/main.py", line 241, in getting_photos
    withdrawal_of_hotels(user)
  File "/home/dok2412/PycharmProjects/python_basic/python_basic/python_basic_diploma/main.py", line 230, in withdrawal_of_hotels
    sqlbase.connecting_to_database(user, 'добавление')
  File "/home/dok2412/PycharmProjects/python_basic/python_basic/python_basic_diploma/sqlbase.py", line 44, in connecting_to_database
    data_hotel = json.dumps(user.hotel)
  File "/usr/lib/python3.9/json/__init__.py", line 231, in dumps
    return _default_encoder.encode(obj)
  File "/usr/lib/python3.9/json/encoder.py", line 199, in encode
    chunks = self.iterencode(o, _one_shot=True)
  File "/usr/lib/python3.9/json/encoder.py", line 257, in iterencode
    return _iterencode(o, 0)
  File "/usr/lib/python3.9/json/encoder.py", line 179, in default
    raise TypeError(f'Object of type {o.__class__.__name__} '
TypeError: Object of type InputMediaPhoto is not JSON serializable
2022-04-04 21:04:21,908 - getting_photos - 259 - произошла ошибка: 
Traceback (most recent call last):
  File "/home/dok2412/PycharmProjects/python_basic/python_basic/python_basic_diploma/main.py", line 241, in getting_photos
    user.hotel = lowprice.sorting_hotels(user)
  File "/home/dok2412/PycharmProjects/python_basic/python_basic/python_basic_diploma/selection/lowprice.py", line 49, in sorting_hotels
    grouping_photo = formation_of_photos(user, id)
  File "/home/dok2412/PycharmProjects/python_basic/python_basic/python_basic_diploma/selection/lowprice.py", line 75, in formation_of_photos
    for i_photo_info in date.get('hotelImages'):
TypeError: 'NoneType' object is not iterable
2022-04-04 21:06:03,932 - getting_photos - 261 - произошла ошибка: 
Traceback (most recent call last):
  File "/home/dok2412/PycharmProjects/python_basic/python_basic/python_basic_diploma/main.py", line 241, in getting_photos
    user.hotel = lowprice.sorting_hotels(user)
  File "/home/dok2412/PycharmProjects/python_basic/python_basic/python_basic_diploma/selection/lowprice.py", line 49, in sorting_hotels
    grouping_photo = formation_of_photos(user, id)
  File "/home/dok2412/PycharmProjects/python_basic/python_basic/python_basic_diploma/selection/lowprice.py", line 75, in formation_of_photos
    for i_photo_info in date.get('hotelImages'):
TypeError: 'NoneType' object is not iterable
2022-04-04 21:14:51,528 - getting_photos - 261 - произошла ошибка: 
Traceback (most recent call last):
  File "/home/dok2412/PycharmProjects/python_basic/python_basic/python_basic_diploma/main.py", line 241, in getting_photos
    user.hotel = lowprice.sorting_hotels(user)
  File "/home/dok2412/PycharmProjects/python_basic/python_basic/python_basic_diploma/selection/lowprice.py", line 49, in sorting_hotels
    grouping_photo = formation_of_photos(user, id)
  File "/home/dok2412/PycharmProjects/python_basic/python_basic/python_basic_diploma/selection/lowprice.py", line 75, in formation_of_photos
    for i_photo_info in date.get('hotelImages'):
TypeError: 'NoneType' object is not iterable
2022-04-04 21:16:09,555 - getting_photos - 261 - произошла ошибка: 
Traceback (most recent call last):
  File "/home/dok2412/PycharmProjects/python_basic/python_basic/python_basic_diploma/main.py", line 247, in getting_photos
    withdrawal_of_hotels(user)
  File "/home/dok2412/PycharmProjects/python_basic/python_basic/python_basic_diploma/main.py", line 226, in withdrawal_of_hotels
    bot.send_media_group(message.chat.id, media=media)
  File "/usr/local/lib/python3.9/dist-packages/telebot/__init__.py", line 1355, in send_media_group
    result = apihelper.send_media_group(
  File "/usr/local/lib/python3.9/dist-packages/telebot/apihelper.py", line 496, in send_media_group
    return _make_request(
  File "/usr/local/lib/python3.9/dist-packages/telebot/apihelper.py", line 157, in _make_request
    json_result = _check_result(method_name, result)
  File "/usr/local/lib/python3.9/dist-packages/telebot/apihelper.py", line 184, in _check_result
    raise ApiTelegramException(method_name, result, result_json)
telebot.apihelper.ApiTelegramException: A request to the Telegram API was unsuccessful. Error code: 400. Description: Bad Request: group send failed
2022-04-04 21:19:39,782 - getting_photos - 262 - произошла ошибка: 
Traceback (most recent call last):
  File "/home/dok2412/PycharmProjects/python_basic/python_basic/python_basic_diploma/main.py", line 248, in getting_photos
    withdrawal_of_hotels(user)
  File "/home/dok2412/PycharmProjects/python_basic/python_basic/python_basic_diploma/main.py", line 228, in withdrawal_of_hotels
    sqlbase.connecting_to_database(user, 'добавление')
  File "/home/dok2412/PycharmProjects/python_basic/python_basic/python_basic_diploma/sqlbase.py", line 44, in connecting_to_database
    data_hotel = json.dumps(user.hotel)
  File "/usr/lib/python3.9/json/__init__.py", line 231, in dumps
    return _default_encoder.encode(obj)
  File "/usr/lib/python3.9/json/encoder.py", line 199, in encode
    chunks = self.iterencode(o, _one_shot=True)
  File "/usr/lib/python3.9/json/encoder.py", line 257, in iterencode
    return _iterencode(o, 0)
  File "/usr/lib/python3.9/json/encoder.py", line 179, in default
    raise TypeError(f'Object of type {o.__class__.__name__} '
TypeError: Object of type InputMediaPhoto is not JSON serializable
2022-04-04 21:22:24,347 - getting_photos - 261 - произошла ошибка: 
Traceback (most recent call last):
  File "/home/dok2412/PycharmProjects/python_basic/python_basic/python_basic_diploma/main.py", line 247, in getting_photos
    withdrawal_of_hotels(user)
  File "/home/dok2412/PycharmProjects/python_basic/python_basic/python_basic_diploma/main.py", line 226, in withdrawal_of_hotels
    bot.send_media_group(message.chat.id, media=media)
  File "/usr/local/lib/python3.9/dist-packages/telebot/__init__.py", line 1355, in send_media_group
    result = apihelper.send_media_group(
  File "/usr/local/lib/python3.9/dist-packages/telebot/apihelper.py", line 496, in send_media_group
    return _make_request(
  File "/usr/local/lib/python3.9/dist-packages/telebot/apihelper.py", line 157, in _make_request
    json_result = _check_result(method_name, result)
  File "/usr/local/lib/python3.9/dist-packages/telebot/apihelper.py", line 184, in _check_result
    raise ApiTelegramException(method_name, result, result_json)
telebot.apihelper.ApiTelegramException: A request to the Telegram API was unsuccessful. Error code: 400. Description: Bad Request: group send failed
2022-04-04 21:24:30,916 - getting_photos - 261 - произошла ошибка: 
Traceback (most recent call last):
  File "/home/dok2412/PycharmProjects/python_basic/python_basic/python_basic_diploma/main.py", line 247, in getting_photos
    withdrawal_of_hotels(user)
  File "/home/dok2412/PycharmProjects/python_basic/python_basic/python_basic_diploma/main.py", line 226, in withdrawal_of_hotels
    bot.send_media_group(message.chat.id, media=media)
  File "/usr/local/lib/python3.9/dist-packages/telebot/__init__.py", line 1355, in send_media_group
    result = apihelper.send_media_group(
  File "/usr/local/lib/python3.9/dist-packages/telebot/apihelper.py", line 496, in send_media_group
    return _make_request(
  File "/usr/local/lib/python3.9/dist-packages/telebot/apihelper.py", line 157, in _make_request
    json_result = _check_result(method_name, result)
  File "/usr/local/lib/python3.9/dist-packages/telebot/apihelper.py", line 184, in _check_result
    raise ApiTelegramException(method_name, result, result_json)
telebot.apihelper.ApiTelegramException: A request to the Telegram API was unsuccessful. Error code: 400. Description: Bad Request: group send failed
2022-04-04 21:27:56,574 - getting_photos - 261 - произошла ошибка: 
Traceback (most recent call last):
  File "/home/dok2412/PycharmProjects/python_basic/python_basic/python_basic_diploma/main.py", line 247, in getting_photos
    withdrawal_of_hotels(user)
  File "/home/dok2412/PycharmProjects/python_basic/python_basic/python_basic_diploma/main.py", line 228, in withdrawal_of_hotels
    sqlbase.connecting_to_database(user, 'добавление')
  File "/home/dok2412/PycharmProjects/python_basic/python_basic/python_basic_diploma/sqlbase.py", line 21, in connecting_to_database
    data_hotel = json.dumps(user.hotel)
  File "/usr/lib/python3.9/json/__init__.py", line 231, in dumps
    return _default_encoder.encode(obj)
  File "/usr/lib/python3.9/json/encoder.py", line 199, in encode
    chunks = self.iterencode(o, _one_shot=True)
  File "/usr/lib/python3.9/json/encoder.py", line 257, in iterencode
    return _iterencode(o, 0)
  File "/usr/lib/python3.9/json/encoder.py", line 179, in default
    raise TypeError(f'Object of type {o.__class__.__name__} '
TypeError: Object of type InputMediaPhoto is not JSON serializable
2022-04-04 21:37:45,526 - getting_photos - 261 - произошла ошибка: 
Traceback (most recent call last):
  File "/home/dok2412/PycharmProjects/python_basic/python_basic/python_basic_diploma/main.py", line 247, in getting_photos
    withdrawal_of_hotels(user)
  File "/home/dok2412/PycharmProjects/python_basic/python_basic/python_basic_diploma/main.py", line 228, in withdrawal_of_hotels
    sqlbase.connecting_to_database(user, 'добавление')
  File "/home/dok2412/PycharmProjects/python_basic/python_basic/python_basic_diploma/sqlbase.py", line 22, in connecting_to_database
    data_hotel = json.dumps(user.hotel)
  File "/usr/lib/python3.9/json/__init__.py", line 231, in dumps
    return _default_encoder.encode(obj)
  File "/usr/lib/python3.9/json/encoder.py", line 199, in encode
    chunks = self.iterencode(o, _one_shot=True)
  File "/usr/lib/python3.9/json/encoder.py", line 257, in iterencode
    return _iterencode(o, 0)
  File "/usr/lib/python3.9/json/encoder.py", line 179, in default
    raise TypeError(f'Object of type {o.__class__.__name__} '
TypeError: Object of type InputMediaPhoto is not JSON serializable
2022-04-04 21:39:19,862 - getting_photos - 261 - произошла ошибка: 
Traceback (most recent call last):
  File "/home/dok2412/PycharmProjects/python_basic/python_basic/python_basic_diploma/main.py", line 247, in getting_photos
    withdrawal_of_hotels(user)
  File "/home/dok2412/PycharmProjects/python_basic/python_basic/python_basic_diploma/main.py", line 228, in withdrawal_of_hotels
    sqlbase.connecting_to_database(user, 'добавление')
  File "/home/dok2412/PycharmProjects/python_basic/python_basic/python_basic_diploma/sqlbase.py", line 32, in connecting_to_database
    add_data(user)
TypeError: add_data() missing 2 required positional arguments: 'name' and 'data_hotel'
2022-04-04 21:41:00,613 - getting_photos - 261 - произошла ошибка: 
Traceback (most recent call last):
  File "/home/dok2412/PycharmProjects/python_basic/python_basic/python_basic_diploma/main.py", line 247, in getting_photos
    withdrawal_of_hotels(user)
  File "/home/dok2412/PycharmProjects/python_basic/python_basic/python_basic_diploma/main.py", line 228, in withdrawal_of_hotels
    sqlbase.connecting_to_database(user, 'добавление')
  File "/home/dok2412/PycharmProjects/python_basic/python_basic/python_basic_diploma/sqlbase.py", line 31, in connecting_to_database
    add_data(user)
  File "/home/dok2412/PycharmProjects/python_basic/python_basic/python_basic_diploma/sqlbase.py", line 24, in add_data
    data_hotel = json.dumps(user.hotel)
  File "/usr/lib/python3.9/json/__init__.py", line 231, in dumps
    return _default_encoder.encode(obj)
  File "/usr/lib/python3.9/json/encoder.py", line 199, in encode
    chunks = self.iterencode(o, _one_shot=True)
  File "/usr/lib/python3.9/json/encoder.py", line 257, in iterencode
    return _iterencode(o, 0)
  File "/usr/lib/python3.9/json/encoder.py", line 179, in default
    raise TypeError(f'Object of type {o.__class__.__name__} '
TypeError: Object of type InputMediaPhoto is not JSON serializable
2022-04-05 23:18:01,249 - distance_center - 356 - произошла ошибка: 
Traceback (most recent call last):
  File "/home/dok2412/PycharmProjects/python_basic/python_basic/python_basic_diploma/main.py", line 331, in distance_center
    user.hotel = bestdeal.sorting_hotels(user)
  File "/home/dok2412/PycharmProjects/python_basic/python_basic/python_basic_diploma/selection/bestdeal.py", line 58, in sorting_hotels
    if int(user.minimum_price) < int(prise_reconciliation) \
ValueError: invalid literal for int() with base 10: ''
2022-04-05 23:18:29,227 - distance_center - 356 - произошла ошибка: 
Traceback (most recent call last):
  File "/home/dok2412/PycharmProjects/python_basic/python_basic/python_basic_diploma/main.py", line 331, in distance_center
    user.hotel = bestdeal.sorting_hotels(user)
  File "/home/dok2412/PycharmProjects/python_basic/python_basic/python_basic_diploma/selection/bestdeal.py", line 58, in sorting_hotels
    if int(user.minimum_price) < int(prise_reconciliation) \
ValueError: invalid literal for int() with base 10: ''
2022-04-05 23:37:59,648 - distance_center - 359 - произошла ошибка: 
Traceback (most recent call last):
  File "/home/dok2412/PycharmProjects/python_basic/python_basic/python_basic_diploma/main.py", line 335, in distance_center
    user.hotel = bestdeal.sorting_hotels(user)
  File "/home/dok2412/PycharmProjects/python_basic/python_basic/python_basic_diploma/selection/bestdeal.py", line 58, in sorting_hotels
    if int(user.minimum_price) < int(prise_reconciliation) < int(user.max_price) and int(distance_center) < int(user.to_the_center):
ValueError: invalid literal for int() with base 10: ''
2022-04-05 23:39:59,766 - distance_center - 359 - произошла ошибка: 
Traceback (most recent call last):
  File "/home/dok2412/PycharmProjects/python_basic/python_basic/python_basic_diploma/main.py", line 335, in distance_center
    user.hotel = bestdeal.sorting_hotels(user)
  File "/home/dok2412/PycharmProjects/python_basic/python_basic/python_basic_diploma/selection/bestdeal.py", line 58, in sorting_hotels
    if int(user.minimum_price) < int(prise_reconciliation) < int(user.max_price) and int(distance_center) < int(user.to_the_center):
ValueError: invalid literal for int() with base 10: ''
2022-04-05 23:42:54,259 - distance_center - 359 - произошла ошибка: 
Traceback (most recent call last):
  File "/home/dok2412/PycharmProjects/python_basic/python_basic/python_basic_diploma/main.py", line 335, in distance_center
    user.hotel = bestdeal.sorting_hotels(user)
  File "/home/dok2412/PycharmProjects/python_basic/python_basic/python_basic_diploma/selection/bestdeal.py", line 60, in sorting_hotels
    if int(user.minimum_price) < int(prise_reconciliation) < int(user.max_price) and int(distance_center) < int(user.to_the_center):
ValueError: invalid literal for int() with base 10: ''
2022-04-05 23:55:55,902 - distance_center - 359 - произошла ошибка: 
Traceback (most recent call last):
  File "/home/dok2412/PycharmProjects/python_basic/python_basic/python_basic_diploma/main.py", line 335, in distance_center
    user.hotel = bestdeal.sorting_hotels(user)
  File "/home/dok2412/PycharmProjects/python_basic/python_basic/python_basic_diploma/selection/bestdeal.py", line 63, in sorting_hotels
    if int(user.minimum_price) < int(prise_reconciliation) < int(user.max_price) and int(distance_center) < int(user.to_the_center):
ValueError: invalid literal for int() with base 10: ''
2022-04-06 00:36:54,855 - getting_photos - 265 - произошла ошибка: 
Traceback (most recent call last):
  File "/home/dok2412/PycharmProjects/python_basic/python_basic/python_basic_diploma/main.py", line 246, in getting_photos
    withdrawal_of_hotels(user)
  File "/home/dok2412/PycharmProjects/python_basic/python_basic/python_basic_diploma/main.py", line 229, in withdrawal_of_hotels
    bot.send_media_group(message.chat.id, media=media)
  File "/usr/local/lib/python3.9/dist-packages/telebot/__init__.py", line 1355, in send_media_group
    result = apihelper.send_media_group(
  File "/usr/local/lib/python3.9/dist-packages/telebot/apihelper.py", line 496, in send_media_group
    return _make_request(
  File "/usr/local/lib/python3.9/dist-packages/telebot/apihelper.py", line 157, in _make_request
    json_result = _check_result(method_name, result)
  File "/usr/local/lib/python3.9/dist-packages/telebot/apihelper.py", line 184, in _check_result
    raise ApiTelegramException(method_name, result, result_json)
telebot.apihelper.ApiTelegramException: A request to the Telegram API was unsuccessful. Error code: 400. Description: Bad Request: group send failed
2022-04-08 20:07:14,992 - checking_the_input - 178 - произошла ошибка: 
Traceback (most recent call last):
  File "/home/dok2412/PycharmProjects/python_basic/python_basic/python_basic_diploma/main.py", line 160, in checking_the_input
    if 0 < int(message.text) < 25:
ValueError: invalid literal for int() with base 10: 'д'
2022-04-08 20:07:25,347 - getting_photos - 308 - произошла ошибка: 
Traceback (most recent call last):
  File "/home/dok2412/PycharmProjects/python_basic/python_basic/python_basic_diploma/main.py", line 277, in getting_photos
    if int(message.text) > 0:
ValueError: invalid literal for int() with base 10: 'д'
2022-04-26 14:07:09,048 - request_to_server - 23 - произошла ошибка: 
Traceback (most recent call last):
  File "/usr/local/lib/python3.9/dist-packages/urllib3/connectionpool.py", line 346, in _make_request
    self._validate_conn(conn)
  File "/usr/local/lib/python3.9/dist-packages/urllib3/connectionpool.py", line 850, in _validate_conn
    conn.connect()
  File "/usr/local/lib/python3.9/dist-packages/urllib3/connection.py", line 319, in connect
    self.sock = ssl_wrap_socket(
  File "/usr/local/lib/python3.9/dist-packages/urllib3/util/ssl_.py", line 329, in ssl_wrap_socket
    return context.wrap_socket(sock, server_hostname=server_hostname)
  File "/usr/lib/python3.9/ssl.py", line 500, in wrap_socket
    return self.sslsocket_class._create(
  File "/usr/lib/python3.9/ssl.py", line 1040, in _create
    self.do_handshake()
  File "/usr/lib/python3.9/ssl.py", line 1309, in do_handshake
    self._sslobj.do_handshake()
socket.timeout: _ssl.c:1112: The handshake operation timed out

During handling of the above exception, another exception occurred:

Traceback (most recent call last):
  File "/usr/local/lib/python3.9/dist-packages/requests/adapters.py", line 430, in send
    resp = conn.urlopen(
  File "/usr/local/lib/python3.9/dist-packages/urllib3/connectionpool.py", line 638, in urlopen
    retries = retries.increment(method, url, error=e, _pool=self,
  File "/usr/local/lib/python3.9/dist-packages/urllib3/util/retry.py", line 357, in increment
    raise six.reraise(type(error), error, _stacktrace)
  File "/usr/local/lib/python3.9/dist-packages/urllib3/packages/six.py", line 686, in reraise
    raise value
  File "/usr/local/lib/python3.9/dist-packages/urllib3/connectionpool.py", line 598, in urlopen
    httplib_response = self._make_request(conn, method, url,
  File "/usr/local/lib/python3.9/dist-packages/urllib3/connectionpool.py", line 349, in _make_request
    self._raise_timeout(err=e, url=url, timeout_value=conn.timeout)
  File "/usr/local/lib/python3.9/dist-packages/urllib3/connectionpool.py", line 309, in _raise_timeout
    raise ReadTimeoutError(self, url, "Read timed out. (read timeout=%s)" % timeout_value)
urllib3.exceptions.ReadTimeoutError: HTTPSConnectionPool(host='hotels4.p.rapidapi.com', port=443): Read timed out. (read timeout=9)

During handling of the above exception, another exception occurred:

Traceback (most recent call last):
  File "/home/dok2412/PycharmProjects/python_basic/python_basic/python_basic_diploma/selection/search_areas.py", line 19, in request_to_server
    response = requests.request("GET", url, headers=headers, params=querystring, timeout=9)
  File "/usr/local/lib/python3.9/dist-packages/requests/api.py", line 58, in request
    return session.request(method=method, url=url, **kwargs)
  File "/usr/local/lib/python3.9/dist-packages/requests/sessions.py", line 508, in request
    resp = self.send(prep, **send_kwargs)
  File "/usr/local/lib/python3.9/dist-packages/requests/sessions.py", line 618, in send
    r = adapter.send(request, **kwargs)
  File "/usr/local/lib/python3.9/dist-packages/requests/adapters.py", line 521, in send
    raise ReadTimeout(e, request=request)
requests.exceptions.ReadTimeout: HTTPSConnectionPool(host='hotels4.p.rapidapi.com', port=443): Read timed out. (read timeout=9)
